Workbook

Sheet Sheet1
A1: 名称 1 | B1: 供应商 | C1: 国 | D1: 名称 1 | E1: 城市 | F1: 地区 | G1: 地址 | H1: 街道 | I1: 组 | J1: 语言 | K1: 电话1 | L1: 税号 5 | M1: 标题 | N1: 公司 | O1: 日期 | P1: 创建者 | Q1: AGrp | R1: Tr.prt | S1: 标题
A2: 北京西飞世纪门窗幕墙工程有限责任公司 | B2: 4000002942 | C2: CN | D2: 北京西飞世纪门窗幕墙工程有限责任公司 | E2: 北京 | F2: 北京 | G2: 106658 | H2: 北京 | I2: Z004 | J2: ZH | L2: 999 | N2: 9776 | O2: 42735 | P2: FI01 | S2: 公司
A3: 北京燕侨物业管理有限公司 | B3: 2000001624 | C3: CN | D3: 北京燕侨物业管理有限公司 | F3: 北京市 | G3: 106597 | H3: 北京市朝阳区建国门外大街24号 | I3: Z002 | J3: ZH | K3: 010-65150326 | L3: 91110105600004996U | N3: 9776 | O3: 42735 | P3: FI01 | S3: 公司
A4: 戴勇 | B4: 2000001625 | C4: CN | D4: 戴勇 | E4: 上海市 | F4: 上海市 | G4: 106598 | H4: 上海浦东新区云台路 | I4: Z002 | J4: ZH | K4: 18113652781 | L4: 310107198701200317 | N4: 9776 | O4: 42735 | P4: FI01 | S4: 先生
A5: 工商银行上海市浦东分行 | B5: 3000000465 | C5: CN | D5: 工商银行上海市浦东分行 | E5: 上海市 | F5: 上海市 | G5: 106599 | H5: 上海市浦东新区浦东南路2024号 | I5: Z003 | J5: ZH | K5: 021-58759075 | L5: 999 | N5: 9776 | O5: 42735 | P5: FI01 | S5: 公司
A6: 金叶俊 | B6: 2000001627 | C6: CN | D6: 金叶俊 | F6: 上海市 | G6: 106601 | H6: 上海普陀区长寿路 | I6: Z002 | J6: ZH | K6: 15801652813 | L6: 999 | N6: 9776 | O6: 42735 | P6: FI01 | S6: 先生
A7: 润森环境服务（上海）有限公司 | B7: 2000001628 | C7: CN | D7: 润森环境服务（上海）有限公司 | E7: 上海市 | F7: 上海市 | G7: 106602 | H7: 上海市普陀区长寿路1076号飞雕商务大厦1902室 | I7: Z002 | J7: ZH | K7: 13585655788 | L7: 91310114078158967C | N7: 9776 | O7: 42735 | P7: FI01 | S7: 公司
A8: 上海安保设备开发工程有限公司 | B8: 1000004348 | C8: CN | D8: 上海安保设备开发工程有限公司 | E8: 上海市 | F8: 上海市 | G8: 106603 | H8: 上海市浦东新区高青路3368号4楼 | I8: Z001 | J8: ZH | K8: 13301602716 | L8: 91310109132202544H | N8: 9776 | O8: 42735 | P8: FI01 | S8: 公司
A9: 上海博世机电设施工程有限公司 | B9: 1000004349 | C9: CN | D9: 上海博世机电设施工程有限公司 | E9: 上海市 | F9: 上海市 | G9: 106604 | H9: 上海浦东大道2515号金茂花园南楼903室 | I9: Z001 | J9: ZH | K9: 13501801873 | L9: 91310112785876001M | N9: 9776 | O9: 42735 | P9: FI01 | S9: 公司
A10: 上海不唯间贸易有限公司 | B10: 2000001629 | C10: CN | D10: 上海不唯间贸易有限公司 | F10: 上海市 | G10: 106605 | H10: 上海嘉定嘉定区安亭镇园区路1168号4幢2736室 | I10: Z002 | J10: ZH | K10: 021-59575884 | L10: 999 | N10: 9776 | O10: 42735 | P10: FI01 | S10: 公司
A11: 上海步景标识有限公司 | B11: 1000004350 | C11: CN | D11: 上海步景标识有限公司 | E11: 上海市 | F11: 上海市 | G11: 106606 | H11: 上海市宝山区沪太路6289弄20号 | I11: Z001 | J11: ZH | K11: 15900793386 | L11: 999 | N11: 9776 | O11: 42735 | P11: FI01 | S11: 公司
A12: 上海春婕花木园艺有限公司 | B12: 2000001631 | C12: CN | D12: 上海春婕花木园艺有限公司 | E12: 上海市 | F12: 上海市 | G12: 106608 | H12: 上海市宝山区漠河路600弄东鼎国际B座903室 | I12: Z002 | J12: ZH | K12: 13122814969 | L12: 913101147639842988 | N12: 9776 | O12: 42735 | P12: FI01 | S12: 公司
A13: 上海大庭信息技术有限公司 | B13: 2000001632 | C13: CN | D13: 上海大庭信息技术有限公司 | E13: 上海市 | F13: 上海市 | G13: 106609 | H13: 上海市金山区朱泾镇秀州村胜利7028号一栋110室 | I13: Z002 | J13: ZH | K13: 13916679647 | L13: 999 | N13: 9776 | O13: 42735 | P13: FI01 | S13: 公司
A14: 上海德翊工程机电设备有限公司 | B14: 1000004351 | C14: CN | D14: 上海德翊工程机电设备有限公司 | E14: 上海市 | F14: 上海市 | G14: 106610 | H14: 上海市黄浦区北京西路142弄2号边门 | I14: Z001 | J14: ZH | K14: 021-63150795 | L14: 913101157956293702 | N14: 9776 | O14: 42735 | P14: FI01 | S14: 公司
A15: 上海斗牛士牛排馆有限公司 | B15: 2000001633 | C15: CN | D15: 上海斗牛士牛排馆有限公司 | E15: 上海市 | F15: 上海市 | G15: 106611 | H15: 上海市徐汇区岳阳路1号 | I15: Z002 | J15: ZH | K15: 021-64332842 | L15: 999 | N15: 9776 | O15: 42735 | P15: FI01 | S15: 公司
A16: 上海泛远皇普信息技术股份有限公司 | B16: 3000000470 | C16: CN | D16: 上海泛远皇普信息技术股份有限公司 | F16: 上海市 | G16: 106653 | H16: 上海市黄浦区打浦路15号3803-1室 | I16: Z003 | J16: ZH | K16: 021-51532025 | L16: 91310000680978570B | N16: 9776 | O16: 42735 | P16: FI01 | S16: 公司
A17: 上海富程环保工程有限公司 | B17: 1000004352 | C17: CN | D17: 上海富程环保工程有限公司 | E17: 上海市 | F17: 上海市 | G17: 106612 | H17: 上海市万航渡路888号23F | I17: Z001 | J17: ZH | K17: 15301692053 | L17: 913102306840419299 | N17: 9776 | O17: 42735 | P17: FI01 | S17: 公司
A18: 上海高力国际物业服务有限公司 | B18: 3000000116 | C18: CN | D18: 上海高力国际物业服务有限公司 | E18: 上海 | G18: 49706 | H18: 上海浦东银城中路600弄 | I18: Z003 | J18: ZH | K18: 021-68881623 | L18: 310115400037173 | N18: 9776 | O18: 42735 | P18: FI01 | S18: 公司
A19: 上海谷泉建筑工程有限公司 | B19: 1000004353 | C19: CN | D19: 上海谷泉建筑工程有限公司 | E19: 上海市 | F19: 上海市 | G19: 106614 | H19: 上海市闸北区虬江路1150弄局东村22号 | I19: Z001 | J19: ZH | K19: 021-54935677 | L19: 999 | N19: 9776 | O19: 42735 | P19: FI01 | S19: 公司
A20: 上海海燕建筑工程有限公司 | B20: 1000004373 | C20: CN | D20: 上海海燕建筑工程有限公司 | F20: 上海市 | G20: 106654 | H20: 上海市浦东新区老港镇良欣路456号2幢452室 | I20: Z001 | J20: ZH | K20: 021-51087738 | L20: 91310115133952267G | N20: 9776 | O20: 42735 | P20: FI01 | S20: 公司
A21: 上海和瀚文化传播有限公司 | B21: 3000000466 | C21: CN | D21: 上海和瀚文化传播有限公司 | E21: 上海市 | F21: 上海市 | G21: 106615 | H21: 上海市云台路92号102室 | I21: Z003 | J21: ZH | K21: 13918309046 | L21: 913101145997659570 | N21: 9776 | O21: 42735 | P21: FI01 | S21: 公司
A22: 上海恒达广告有限公司 | B22: 3000000467 | C22: CN | D22: 上海恒达广告有限公司 | E22: 上海市 | F22: 上海市 | G22: 106616 | H22: 上海市闵行区纪翟路西花园25号 | I22: Z003 | J22: ZH | K22: 15800344088 | L22: 999 | N22: 9776 | O22: 42735 | P22: FI01 | S22: 公司
A23: 上海恒建设发展有限公司 | B23: 4000002943 | C23: CN | D23: 上海恒建设发展有限公司 | E23: 上海 | F23: 上海 | G23: 106659 | H23: 上海 | I23: Z004 | J23: ZH | L23: 999 | N23: 9776 | O23: 42735 | P23: FI01 | S23: 公司
A24: 上海恒盈建设发展有限公司 | B24: 1000004354 | C24: CN | D24: 上海恒盈建设发展有限公司 | E24: 上海市 | F24: 上海市 | G24: 106617 | H24: 上海市普陀区岚皋路597号十八英尺312室 | I24: Z001 | J24: ZH | K24: 13816076056 | L24: 91310113743758357L | N24: 9776 | O24: 42735 | P24: FI01 | S24: 公司
A25: 上海弘韬建设发展有限公司 | B25: 1000004355 | C25: CN | D25: 上海弘韬建设发展有限公司 | E25: 上海市 | F25: 上海市 | G25: 106618 | H25: 上海市黄浦区光启南路78号-2 | I25: Z001 | J25: ZH | K25: 13816405637 | L25: 999 | N25: 9776 | O25: 42735 | P25: FI01 | S25: 公司
A26: 上海宏源达防水工程有限公司 | B26: 1000004356 | C26: CN | D26: 上海宏源达防水工程有限公司 | E26: 上海市 | F26: 上海市 | G26: 106619 | H26: 上海市申滨陆1051弄100号1202室 | I26: Z001 | J26: ZH | K26: 13916892330 | L26: 999 | N26: 9776 | O26: 42735 | P26: FI01 | S26: 公司
A27: 上海环境节能工程股份有限公司 | B27: 1000004357 | C27: CN | D27: 上海环境节能工程股份有限公司 | E27: 上海市 | F27: 上海市 | G27: 106620 | H27: 上海市曲阳路158号北区4楼 | I27: Z001 | J27: ZH | K27: 021-65090068 | L27: 999 | N27: 9776 | O27: 42735 | P27: FI01 | S27: 公司
A28: 上海汇昕文化传播有限公司 | B28: 3000000468 | C28: CN | D28: 上海汇昕文化传播有限公司 | E28: 上海市 | F28: 上海市 | G28: 106621 | H28: 上海市漕宝路86号光大会展f座1904室 | I28: Z003 | J28: ZH | K28: 13611973999 | L28: 913102305852476811 | N28: 9776 | O28: 42735 | P28: FI01 | S28: 公司
A29: 上海嘉好图文设计制作有限公司 | B29: 3000000469 | C29: CN | D29: 上海嘉好图文设计制作有限公司 | F29: 上海市 | G29: 106622 | H29: 上海市嘉定区云屏路1399弄23-25号1305室 | I29: Z003 | J29: ZH | K29: 18106182318 | L29: 91310116057607882T | N29: 9776 | O29: 42735 | P29: FI01 | S29: 公司
A30: 上海静盛装饰设计有限公司 | B30: 1000004374 | C30: CN | D30: 上海静盛装饰设计有限公司 | F30: 上海市 | G30: 106655 | H30: 上海市崇明县庙镇窑桥村社南758号1幢1175室（上海庙镇经济开发区） | I30: Z001 | J30: ZH | K30: 13501685113 | L30: 91310230566524559M | N30: 9776 | O30: 42735 | P30: FI01 | S30: 公司
A31: 上海久合机电工程成套公司 | B31: 1000004358 | C31: CN | D31: 上海久合机电工程成套公司 | E31: 上海市 | F31: 上海市 | G31: 106623 | H31: 上海水电路300号（金鸿苑）12幢2单元101室 | I31: Z001 | J31: ZH | K31: 13701988075 | L31: 310115132319275 | N31: 9776 | O31: 42735 | P31: FI01 | S31: 公司
A32: 上海聚怡清洗服务有限公司 | B32: 2000001635 | C32: CN | D32: 上海聚怡清洗服务有限公司 | E32: 上海市 | F32: 上海市 | G32: 106624 | H32: 上海市嘉定区菊园新区树屏路588弄19号2022室 | I32: Z002 | J32: ZH | K32: 18932152521 | L32: 91310114078189958W | N32: 9776 | O32: 42735 | P32: FI01 | S32: 公司
A33: 上海克灵思容一环境工程事务所 | B33: 2000001636 | C33: CN | D33: 上海克灵思容一环境工程事务所 | E33: 上海市 | F33: 上海市 | G33: 106625 | H33: 上海市长宁区789号1号楼1104室 | I33: Z002 | J33: ZH | K33: 13916147910 | L33: 91310118560149348R | N33: 9776 | O33: 42735 | P33: FI01 | S33: 公司
A34: 上海霖实清洗服务有限公司 | B34: 4000002944 | C34: CN | D34: 上海霖实清洗服务有限公司 | E34: 上海 | F34: 上海 | G34: 106660 | H34: 上海 | I34: Z004 | J34: ZH | L34: 999 | N34: 9776 | O34: 42735 | P34: FI01 | S34: 公司
A35: 上海霖实清洗服务有限公司计数 | B35: 2000001637 | C35: CN | D35: 上海霖实清洗服务有限公司计数 | E35: 上海市 | F35: 上海市 | G35: 106626 | H35: 上海市徐汇区田林路89弄35号1106室 | I35: Z002 | J35: ZH | K35: 021-64515160 | L35: 91310120745639220U | N35: 9776 | O35: 42735 | P35: FI01 | S35: 公司
A36: 上海普环实业有限公司第三分公司 | B36: 2000001638 | C36: CN | D36: 上海普环实业有限公司第三分公司 | E36: 上海市 | F36: 上海市 | G36: 106627 | H36: 上海市丹巴路1720号 | I36: Z002 | J36: ZH | K36: 13764955501 | L36: 913101077683748439 | N36: 9776 | O36: 42735 | P36: FI01 | S36: 公司
A37: 上海燃气（集团）有限公司 | B37: 2000001639 | C37: CN | D37: 上海燃气（集团）有限公司 | F37: 上海市 | G37: 106628 | H37: 上海市安远路706号 | I37: Z002 | J37: ZH | K37: 021-962777 | L37: 999 | N37: 9776 | O37: 42735 | P37: FI01 | S37: 公司
A38: 上海赛奕实业有限公司 | B38: 1000004359 | C38: CN | D38: 上海赛奕实业有限公司 | E38: 上海市 | F38: 上海市 | G38: 106629 | H38: 上海市九星路16号二楼A30 | I38: Z001 | J38: ZH | K38: 15901659941 | L38: 9131011655000847XU | N38: 9776 | O38: 42735 | P38: FI01 | S38: 公司
A39: 上海申煤燃气工程有限公司 | B39: 1000004360 | C39: CN | D39: 上海申煤燃气工程有限公司 | F39: 上海市 | G39: 106630 | H39: 上海市黄浦区制造局路437号181室 | I39: Z001 | J39: ZH | K39: 15239852175 | L39: 91310101744200064P | N39: 9776 | O39: 42735 | P39: FI01 | S39: 公司
A40: 上海饰国建筑工程有限公司 | B40: 1000004375 | C40: CN | D40: 上海饰国建筑工程有限公司 | F40: 上海市 | G40: 106656 | H40: 上海市崇明县长兴镇潘园公路1800号2号楼5071室（上海泰和经济发展 | I40: Z001 | J40: ZH | K40: 13601649703 | L40: 999 | N40: 9776 | O40: 42735 | P40: FI01 | S40: 公司
...

Sheet Sheet2
A1: 北京燕侨物业管理有限公司 | B1: =VLOOKUP(A1,Sheet1!$A$2:$B$94,2,FALSE) -> 2000001624
A2: 戴勇 | B2: =VLOOKUP(A2,Sheet1!$A$2:$B$94,2,FALSE) -> 2000001625
A3: 工商银行上海市浦东分行 | B3: =VLOOKUP(A3,Sheet1!$A$2:$B$94,2,FALSE) -> 3000000465
A4: 国网上海市电力公司 | B4: =VLOOKUP(A4,Sheet1!$A$2:$B$94,2,FALSE) -> 1000001541
A5: 金叶俊 | B5: =VLOOKUP(A5,Sheet1!$A$2:$B$94,2,FALSE) -> 2000001627
A6: 润森环境服务（上海）有限公司 | B6: =VLOOKUP(A6,Sheet1!$A$2:$B$94,2,FALSE) -> 2000001628
A7: 上海安保设备开发工程有限公司 | B7: =VLOOKUP(A7,Sheet1!$A$2:$B$94,2,FALSE) -> 1000004348
A8: 上海博世机电设施工程有限公司 | B8: =VLOOKUP(A8,Sheet1!$A$2:$B$94,2,FALSE) -> 1000004349
A9: 上海不唯间贸易有限公司 | B9: =VLOOKUP(A9,Sheet1!$A$2:$B$94,2,FALSE) -> 2000001629
A10: 上海步景标识有限公司 | B10: =VLOOKUP(A10,Sheet1!$A$2:$B$94,2,FALSE) -> 1000004350
A11: 上海城投水务（集团）有限公司 | B11: =VLOOKUP(A11,Sheet1!$A$2:$B$94,2,FALSE) -> 1000001315
A12: 上海春婕花木园艺有限公司 | B12: =VLOOKUP(A12,Sheet1!$A$2:$B$94,2,FALSE) -> 2000001631
... A82: 其他 | B82: =VLOOKUP(A82,Sheet1!$A$2:$B$94,2,FALSE) -> 4000000680
